nohup: ignoring input
INFO:root:Downloading and generating the schema...
INFO:root:Generated the schema for 2019_05_13. A database will be created at mysql+pymysql://innovationMaster:innovationmapping@innovation-mapping-mysql-mysql5721.ci9272ypsbyf.eu-west-2.rds.amazonaws.com/patstat_2019_05_13
INFO:root:Skipping download/files/2019/05/13/1557744759414/index_documentation_scripts_PATSTAT_Global_2019_Spring.zip
INFO:root:Skipping download/files/2019/05/13/1557744782230/data_PATSTAT_Global_2019_Spring_01.zip
INFO:root:Skipping download/files/2019/05/13/1557746142379/data_PATSTAT_Global_2019_Spring_02.zip
INFO:root:Skipping download/files/2019/05/13/1557747404920/data_PATSTAT_Global_2019_Spring_03.zip
INFO:root:Skipping download/files/2019/05/13/1557748373770/data_PATSTAT_Global_2019_Spring_04.zip
INFO:root:Skipping download/files/2019/05/13/1557750095304/data_PATSTAT_Global_2019_Spring_05.zip
INFO:root:Processing file download/files/2019/05/13/1557751862915/data_PATSTAT_Global_2019_Spring_06.zip...
INFO:root:		Skipping tls212_part02.zip
INFO:root:		Skipping tls214_part01.zip
INFO:root:		Skipping tls214_part02.zip
INFO:root:		Skipping tls215_part01.zip
INFO:root:		Skipping tls216_part01.zip
INFO:root:	Processing nested file tls222_part01.zip...
INFO:root:		Retrieved class from table name tls222.
Traceback (most recent call last):
  File "/home/ec2-user/miniconda3/envs/py36/lib/python3.6/site-packages/sqlalchemy/engine/base.py", line 1229, in _execute_context
    cursor, statement, parameters, context
  File "/home/ec2-user/miniconda3/envs/py36/lib/python3.6/site-packages/sqlalchemy/dialects/mysql/mysqldb.py", line 148, in do_executemany
    rowcount = cursor.executemany(statement, parameters)
  File "/home/ec2-user/miniconda3/envs/py36/lib/python3.6/site-packages/pymysql/cursors.py", line 197, in executemany
    self._get_db().encoding)
  File "/home/ec2-user/miniconda3/envs/py36/lib/python3.6/site-packages/pymysql/cursors.py", line 234, in _do_execute_many
    rows += self.execute(sql + postfix)
  File "/home/ec2-user/miniconda3/envs/py36/lib/python3.6/site-packages/pymysql/cursors.py", line 170, in execute
    result = self._query(query)
  File "/home/ec2-user/miniconda3/envs/py36/lib/python3.6/site-packages/pymysql/cursors.py", line 328, in _query
    conn.query(q)
  File "/home/ec2-user/miniconda3/envs/py36/lib/python3.6/site-packages/pymysql/connections.py", line 517, in query
    self._affected_rows = self._read_query_result(unbuffered=unbuffered)
  File "/home/ec2-user/miniconda3/envs/py36/lib/python3.6/site-packages/pymysql/connections.py", line 732, in _read_query_result
    result.read()
  File "/home/ec2-user/miniconda3/envs/py36/lib/python3.6/site-packages/pymysql/connections.py", line 1075, in read
    first_packet = self.connection._read_packet()
  File "/home/ec2-user/miniconda3/envs/py36/lib/python3.6/site-packages/pymysql/connections.py", line 684, in _read_packet
    packet.check_error()
  File "/home/ec2-user/miniconda3/envs/py36/lib/python3.6/site-packages/pymysql/protocol.py", line 220, in check_error
    err.raise_mysql_exception(self._data)
  File "/home/ec2-user/miniconda3/envs/py36/lib/python3.6/site-packages/pymysql/err.py", line 109, in raise_mysql_exception
    raise errorclass(errno, errval)
pymysql.err.InternalError: (1053, 'Server shutdown in progress')

During handling of the above exception, another exception occurred:

Traceback (most recent call last):
  File "/home/ec2-user/miniconda3/envs/py36/lib/python3.6/site-packages/sqlalchemy/engine/base.py", line 739, in _rollback_impl
    self.engine.dialect.do_rollback(self.connection)
  File "/home/ec2-user/miniconda3/envs/py36/lib/python3.6/site-packages/sqlalchemy/dialects/mysql/base.py", line 2253, in do_rollback
    dbapi_connection.rollback()
  File "/home/ec2-user/miniconda3/envs/py36/lib/python3.6/site-packages/pymysql/connections.py", line 430, in rollback
    self._read_ok_packet()
  File "/home/ec2-user/miniconda3/envs/py36/lib/python3.6/site-packages/pymysql/connections.py", line 394, in _read_ok_packet
    pkt = self._read_packet()
  File "/home/ec2-user/miniconda3/envs/py36/lib/python3.6/site-packages/pymysql/connections.py", line 657, in _read_packet
    packet_header = self._read_bytes(4)
  File "/home/ec2-user/miniconda3/envs/py36/lib/python3.6/site-packages/pymysql/connections.py", line 707, in _read_bytes
    CR.CR_SERVER_LOST, "Lost connection to MySQL server during query")
pymysql.err.OperationalError: (2013, 'Lost connection to MySQL server during query')

The above exception was the direct cause of the following exception:

Traceback (most recent call last):
  File "data_loader.py", line 249, in <module>
    n_jobs=1)
  File "data_loader.py", line 236, in download_patstat_to_db
    pwd=patstat_pwd)
  File "data_loader.py", line 205, in _download_patstat_to_db
    restart_filename=restart_filename)
  File "data_loader.py", line 170, in zipfile_to_db
    filter_pks=restarting)
  File "data_loader.py", line 135, in write_to_db
    conn.execute(_class.__table__.insert(), rows)
  File "/home/ec2-user/miniconda3/envs/py36/lib/python3.6/site-packages/sqlalchemy/engine/base.py", line 988, in execute
    return meth(self, multiparams, params)
  File "/home/ec2-user/miniconda3/envs/py36/lib/python3.6/site-packages/sqlalchemy/sql/elements.py", line 287, in _execute_on_connection
    return connection._execute_clauseelement(self, multiparams, params)
  File "/home/ec2-user/miniconda3/envs/py36/lib/python3.6/site-packages/sqlalchemy/engine/base.py", line 1107, in _execute_clauseelement
    distilled_params,
  File "/home/ec2-user/miniconda3/envs/py36/lib/python3.6/site-packages/sqlalchemy/engine/base.py", line 1253, in _execute_context
    e, statement, parameters, cursor, context
  File "/home/ec2-user/miniconda3/envs/py36/lib/python3.6/site-packages/sqlalchemy/engine/base.py", line 1468, in _handle_dbapi_exception
    self._autorollback()
  File "/home/ec2-user/miniconda3/envs/py36/lib/python3.6/site-packages/sqlalchemy/util/langhelpers.py", line 79, in __exit__
    compat.reraise(type_, value, traceback)
  File "/home/ec2-user/miniconda3/envs/py36/lib/python3.6/site-packages/sqlalchemy/util/compat.py", line 153, in reraise
    raise value
  File "/home/ec2-user/miniconda3/envs/py36/lib/python3.6/site-packages/sqlalchemy/engine/base.py", line 1468, in _handle_dbapi_exception
    self._autorollback()
  File "/home/ec2-user/miniconda3/envs/py36/lib/python3.6/site-packages/sqlalchemy/engine/base.py", line 867, in _autorollback
    self._root._rollback_impl()
  File "/home/ec2-user/miniconda3/envs/py36/lib/python3.6/site-packages/sqlalchemy/engine/base.py", line 741, in _rollback_impl
    self._handle_dbapi_exception(e, None, None, None, None)
  File "/home/ec2-user/miniconda3/envs/py36/lib/python3.6/site-packages/sqlalchemy/engine/base.py", line 1384, in _handle_dbapi_exception
    exc_info,
  File "/home/ec2-user/miniconda3/envs/py36/lib/python3.6/site-packages/sqlalchemy/util/compat.py", line 398, in raise_from_cause
    reraise(type(exception), exception, tb=exc_tb, cause=cause)
  File "/home/ec2-user/miniconda3/envs/py36/lib/python3.6/site-packages/sqlalchemy/util/compat.py", line 152, in reraise
    raise value.with_traceback(tb)
  File "/home/ec2-user/miniconda3/envs/py36/lib/python3.6/site-packages/sqlalchemy/engine/base.py", line 739, in _rollback_impl
    self.engine.dialect.do_rollback(self.connection)
  File "/home/ec2-user/miniconda3/envs/py36/lib/python3.6/site-packages/sqlalchemy/dialects/mysql/base.py", line 2253, in do_rollback
    dbapi_connection.rollback()
  File "/home/ec2-user/miniconda3/envs/py36/lib/python3.6/site-packages/pymysql/connections.py", line 430, in rollback
    self._read_ok_packet()
  File "/home/ec2-user/miniconda3/envs/py36/lib/python3.6/site-packages/pymysql/connections.py", line 394, in _read_ok_packet
    pkt = self._read_packet()
  File "/home/ec2-user/miniconda3/envs/py36/lib/python3.6/site-packages/pymysql/connections.py", line 657, in _read_packet
    packet_header = self._read_bytes(4)
  File "/home/ec2-user/miniconda3/envs/py36/lib/python3.6/site-packages/pymysql/connections.py", line 707, in _read_bytes
    CR.CR_SERVER_LOST, "Lost connection to MySQL server during query")
sqlalchemy.exc.OperationalError: (pymysql.err.OperationalError) (2013, 'Lost connection to MySQL server during query')
(Background on this error at: http://sqlalche.me/e/e3q8)
